Workbook
Name AWP_ACTIVITES: REF_AWP!$A$2:$A$73
Name AWP_CAT_Commandes_et_Approvisionnement: REF_AWP!$C$151:$C$155
Name AWP_CAT_Coordination_et_Gouvernance: REF_AWP!$H$151:$H$153
Name AWP_CAT_Distribution_et_Livraison: REF_AWP!$E$151:$E$154
Name AWP_CAT_Donnees_et_Reporting: REF_AWP!$F$151:$F$154
Name AWP_CAT_Formation_et_Renforcement_de_Capacites: REF_AWP!$I$151:$I$152
Name AWP_CAT_Gestion_de_Projet: REF_AWP!$J$151:$J$153
Name AWP_CAT_Gestion_de_Stocks: REF_AWP!$D$151:$D$155
Name AWP_CAT_Produits_Specifiques: REF_AWP!$K$151:$K$152
Name AWP_CAT_Quantification_et_Prevision: REF_AWP!$B$151:$B$153
Name AWP_CAT_Systemes_d_Information: REF_AWP!$G$151:$G$155
Name AWP_CATEGORIES: REF_AWP!$A$101:$A$136
Name AWP_T_1_1_1: REF_AWP!$E$2:$E$5
Name AWP_T_1_1_10: REF_AWP!$M$2
Name AWP_T_1_1_11: REF_AWP!$N$2:$N$5
Name AWP_T_1_1_2: REF_AWP!$F$2:$F$3
Name AWP_T_1_1_3: REF_AWP!$G$2
Name AWP_T_1_1_4: REF_AWP!$H$2
Name AWP_T_1_1_5: REF_AWP!$I$2:$I$3
Name AWP_T_1_1_6: REF_AWP!$J$2:$J$3
Name AWP_T_1_1_7: REF_AWP!$K$2
Name AWP_T_1_1_9: REF_AWP!$L$2
Name AWP_T_1_10_1: REF_AWP!$AL$2
Name AWP_T_1_10_2: REF_AWP!$AM$2
Name AWP_T_1_10_3: REF_AWP!$AN$2
Name AWP_T_1_11_1: REF_AWP!$AO$2:$AO$14
Name AWP_T_1_11_2: REF_AWP!$AP$2:$AP$4
Name AWP_T_1_11_3: REF_AWP!$AQ$2:$AQ$5
Name AWP_T_1_11_4: REF_AWP!$AR$2:$AR$9
Name AWP_T_1_11_5: REF_AWP!$AS$2:$AS$8
Name AWP_T_1_11_6: REF_AWP!$AT$2:$AT$14
Name AWP_T_1_2_1: REF_AWP!$O$2:$O$4
Name AWP_T_1_2_2: REF_AWP!$P$2
Name AWP_T_1_2_3: REF_AWP!$Q$2
Name AWP_T_1_3_1: REF_AWP!$R$2:$R$5
Name AWP_T_1_3_2: REF_AWP!$S$2:$S$9
Name AWP_T_1_4_1: REF_AWP!$T$2:$T$5
Name AWP_T_1_5_1: REF_AWP!$U$2
Name AWP_T_1_7_1: REF_AWP!$V$2:$V$3
Name AWP_T_1_7_11: REF_AWP!$AE$2:$AE$3
Name AWP_T_1_7_12: REF_AWP!$AF$2:$AF$9
Name AWP_T_1_7_13: REF_AWP!$AG$2:$AG$5
Name AWP_T_1_7_14: REF_AWP!$AH$2
Name AWP_T_1_7_2: REF_AWP!$W$2:$W$4
Name AWP_T_1_7_3: REF_AWP!$X$2:$X$12
Name AWP_T_1_7_4: REF_AWP!$Y$2:$Y$3
Name AWP_T_1_7_5: REF_AWP!$Z$2
Name AWP_T_1_7_6: REF_AWP!$AA$2:$AA$6
Name AWP_T_1_7_7: REF_AWP!$AB$2
Name AWP_T_1_7_8: REF_AWP!$AC$2
Name AWP_T_1_7_9: REF_AWP!$AD$2:$AD$4
Name AWP_T_1_8_2: REF_AWP!$AI$2
Name AWP_T_1_8_3: REF_AWP!$AJ$2
Name AWP_T_1_9_1: REF_AWP!$AK$2
Name AWP_T_2_1_1: REF_AWP!$AU$2:$AU$5
Name AWP_T_2_1_2: REF_AWP!$AV$2:$AV$9
Name AWP_T_2_2_1: REF_AWP!$AW$2:$AW$5
Name AWP_T_2_2_2: REF_AWP!$AX$2:$AX$6
Name AWP_T_2_2_3: REF_AWP!$AY$2:$AY$3
Name AWP_T_2_2_4: REF_AWP!$AZ$2

Sheet AIDE
A1: AIDE MEMOIRE — BULLETIN HEBDOMADAIRE LHSPLA-TA
A3: OBJECTIF | B3: Alimenter chaque semaine le Bulletin d'Information transmis au Directeur des Opérations (DoS). Il récapitule les activités réalisées la semaine précédente et les activités planifiées sur un mois glissant.
A4: FRÉQUENCE | B4: Hebdomadaire. Chaque entité soumet son onglet chaque LUNDI matin avant 9h00
A5: STRUCTURE | B5: Ce classeur contient 10 onglets : MODE D'EMPLOI + 8 onglets entité (CAD, PMO, QAD, SE, SI, FINANCES, ABIDJAN, BOUAKE) + 1 onglet COMPILATION.
A6: COMMENT REMPLIR | B6: 1. Ouvrir VOTRE onglet (ex : SE pour le service SE). 2. Section A : saisir le Responsable, la Semaine de référence (ex : Du 07/04 au 11/04/2025) et la date de soumission. 3. Section B : décrire chaque activité RÉALISÉE (max 8 lignes — ajouter des lignes si besoin). 4. Section C : planifier les activités PRÉVUES sur les 4 prochaines semaines (max 10 lignes). 5. Section D : signaler tout RISQUE ou point nécessitant une décision / arbitrage (max 5 lignes).
A7: PARTICIPATION DoS | B7: Dans la colonne « Participation DoS ? » (Section C), sélectionner ✅ OUI ou ❌ NON dans le menu déroulant. Toute activité impliquant le DoS doit être signalée AU MOINS 2 SEMAINES avant son démarrage.
A8: CRITICITÉ (Section D) | B8: Utiliser le menu déroulant pour choisir le niveau : 🔴 Critique — Décision urgente requise 🟠 Élevé — Attention forte nécessaire 🟡 Modéré — À surveiller 🟢 Faible — Pour information
A9: COMPILATION AUTO | B9: L'onglet COMPILATION agrège automatiquement les données de tous les onglets entité via des formules. NE PAS modifier directement les cellules de la compilation — elles se mettent à jour automatiquement.
A10: ENVOI | B10: Envoyer le fichier EXCEL complété chaque lundi matin à Charles Oscar LEBRI (c.lebri@npsp.ci). L'objet du mail : [BULLETIN LHSPLA] Semaine du JJ/MM au JJ/MM/YYYY — [Votre entité]
A11: RÈGLES IMPORTANTES | B11: • Ne modifier NI supprimer les formules dans l'onglet COMPILATION. • Les cellules en jaune 🟡 sont les SEULES à renseigner. • Respecter le délai : soumission avant LUNDI 9h00. • En cas de doute, contacter Charles Oscar LEBRI.

Sheet CAD
A1: BULLETIN HEBDOMADAIRE LHSPLA-TA — CANEVAS DE REPORTING ENTITÉ
A2: Entité : CAD – Chaîne d'Approvisionnement Décentralisée
A4: A. INFORMATIONS DE SOUMISSION
A5: Entité | C5: Responsable (Nom & Prénom) | E5: Semaine de référence | G5: Date de soumission
A6: CAD | E6: =SE!E6 -> Du 25/05 au 29/05/2026 | G6: =SE!G6 -> 46174
A8: B. ACTIVITÉS RÉALISÉES — Semaine précédente
A9: ℹ️ Pour chaque activité réalisée au cours de la semaine écoulée, compléter une ligne.
A10: N° | B10: N° Activités | C10: Libellé de la tâche | D10: Objectifs | E10: Lieu | F10: Date(s) | G10: Principales recommandations / Résultats clés
A11: 1 | B11: 1.3-2 | C11: 1.3-2.4 : Organiser des rencontres d'orientation logistique au niveau départemental | D11: · Présenter et analyser les résultats des activités logistiques au niveau des ESPC : rapportage et qualité des données rapportées ; disponibilités des stocks de produits traceurs et Système d’Alerte Précoce ; Gestion des stocks et utilisation de mSupply ; données de la File Active. · Identifier les problèmes à la mise en œuvre des activités au niveau des ESPC · Renforcer les capacités des gestionnaires de pharmacie des ESPC · Formuler des recommandations | E11: DS APA (26/05/2026) | F11: 46168 | G11: Nombre d'acteurs des ESPC présents : 14 acteurs; Les acteurs présents ont été sensibilités sur l'importance du respect du délai de dépôt des RM, coachés sur la qualité des données rapportées en passant en revue les erreurs courantes de rapportage (report mensuel des données; mauvaise unité de rapportage; items insuffisamment renseignés; erreurs de calculs; les incohérences régimes et indicateurs), au SAP et sa mise en oeuvre. Aussi, les acteurs ont été orientés sur la gestion des produits iCCM. Quelques recommandations : Organiser les services en responsabilisant les acteurs; Elaborer et transmettre dans les délais les RM; Valider en interne les données avant transmission des rapports au DS; Utiliser correctement toutes les fonctionnalités de mSupply; Estimer correctement les quantités à allouer en tenant compte des consommations réelles et des nombres de jours de rupture notifiés; Mettre en oeuvre le SAP pour anticiper tous risques de rupture et de péremptione
A12: 2 | B12: 1.3-2 | C12: 1.3-2.2 : Organiser des visites d'assistance technique aux acteurs de la chaîne d'approvisionnement décentralisée | D12: Améliorer la qualité du rapportage, la qualité des prestations et de la gestion des produits et intrants des PNS | F12: Du 25 au 29/05/2026 | G12: Pas de visite réalisée cette semaine
A13: 3 | B13: 1.3-2 | C13: 1.3-2.3 : Apporter un appui technique et financier aux réunions régionales d'analyse et de mise à niveau des stocks | D13: Accompagner les gestionnaires des sites clients directs dans l'exécution effective des plans de redéploiements des stocks issus des réunions d'analyse | E13: Suivi de l'execution des plans de redeploiement élaborés et en cours de réalisation | F13: Du 25 au 29/05/2026 | G13: 1 plan de redéploiement a été élaboré et en cours de réalisation avec l'appui logistique de LHSPLA. Pour les réunions réalisées la semaine du 11 au 15/05/202, le point de suivi de la réalisation des 4 plans de redéploiement est le suivant : Région Moronou (100%); Région Lôh Djiboua (80%); Région Gôh (80%) et Agnéby-Tiassa (80%)
A14: 4 | B14: 1.3-1 | C14: 1.3-1.1 : Faire la mise à jour mensuelle des contacts téléphoniques des prestataires à insérer dans la flotte | D14: Faciliter les échanges d'informations logistiques des produits de santé du niveau central au niveau communautaire
A15: 5 | B15: 1.2-1 | C15: 1.2-1.1 : Faire le suivi la complétude et la promptitude des rapports des sites non clients directs (mSupply, …) | D15: améliorer la disponibilité des produits traceurs au niveau des sites derservis par les districts | E15: Régions sanitaires livrées par l'Agence Régionale de Bouaké | F15: Du 25/05/2026 au 31/05/2026 | G15: Relance sous forme de rappels dans les groupes watsapp de districts pour les differentes tâches à effectuer avec mSupply;
A16: 6 | B16: 1.3-2 | C16: 1.3-2.3 : Apporter un appui technique et financier aux réunions régionales d'analyse et de mise à niveau des stocks | D16: améliorer la disponibilité des produits traceurs des programmes de sante au niveau de chaque région | E16: Bélier, Marahoué,Hambol, Haut-Sassandra, Guémon, et Worodougou | F16: Du 25/05/2026 au 29/05/2026 | G16: suivi de l'excécution des plans de rédeploiement issus des réunions d'analyse des stocks; le taux est de 100% pour le Worodougou, Bélier et Haut-Sassandra
A17: 7 | B17: 1.8-2 | C17: 1.8-2.1 : Organiser des sessions de formation des acteurs de la chaîne d'approvisionnement | D17: Renforcer less capacité techniques des gestionnaires (APGP, IDE et SFDE) des produits de santé des sites péripheriques | E17: Yamoussoukro | F17: 27/05/2026 au 31/05/2026 | G17: Formation de 15 acteurs des ESPC et districts surl'optimisation de la gestion des stocks des produits de santé; entreposage et stockage; prise en main de mSupply; Système d'Alerte Précoce et Assistance Technique. La progression des apprenants etait significative à l'issu des pré et Post-Test
A18: 8
A19: ↳ Ajouter autant de lignes que nécessaire avant soumission.
A21: C. ACTIVITÉS PLANIFIÉES — Mois glissant (4 semaines à venir)
A22: ℹ️ Lister toutes les activités prévues sur les 4 prochaines semaines. Signaler en ROUGE les activités nécessitant la participation du DoS.
A23: N° | B23: N° Activités | C23: Libellé de la tâche | D23: Objectifs | E23: Lieu | F23: Date(s) prévues | G23: Participation DoS ? | H23: Observations / Points d'attention
A24: 1 | B24: 1.3-2 | C24: 1.3-2.3 : Apporter un appui technique et financier aux réunions régionales d'analyse et de mise à niveau des stocks | D24: - Faire le point des recommandations ( suivi du taux de redéploiement, etc.) de la dernière réunion - Faciliter la prise en main du “Weekly Report” pour l’analyse des niveaux de stocks au niveau régional et la prise de décision. - Effectuer les analyses avec les données disponibles pour une prise de décision - Discuter des autres activités et identifier les problèmes à la gestion de la chaîne d’approvisionnement - Proposer un plan d’amélioration ( plans de redéploiements) - Formuler des recommandations | E24: Régions sanitaires Gbôklê; N'zi et Grands Ponts | F24: Du 08 au 12/06/2026 | G24: ❌ NON | H24: Activité reprogrammée : DS Gbôklê (12/06/2026); DS N'zi (date pas encore communiquée); GRANDS PONTS (date pas encore communiquée)
B25: 1.3-2 | C25: 1.3-2.2 : Organiser des visites d'assistance technique aux acteurs de la chaîne d'approvisionnement décentralisée | D25: Améliorer la qualité du rapportage, la qualité des prestations et de la gestion des produits et intrants des PNS et la disponibilité des produits traceurs des PNS | E25: Région Abidjan 2 | F25: Du 01 au 05/06/2026 | G25: ❌ NON | H25: Ces visites de sites de la région Abidjan 2, seront mis à profit pour redéployer les stocks issus du plan de la réunion d'analyse et de mise à niveau des stocks. Afin d'assurer la disponibilité des produits de santé des PNS
A26: 2 | B26: 1.3-2 | C26: 1.3-2.4 : Organiser des rencontres d'orientation logistique au niveau départemental | D26: · Présenter et analyser les résultats des activités logistiques au niveau des ESPC : rapportage et qualité des données rapportées ; disponibilités des stocks de produits traceurs et Système d’Alerte Précoce ; Gestion des stocks et utilisation de mSupply ; données de la File Active. · Identifier les problèmes à la mise en œuvre des activités au niveau des ESPC · Renforcer les capacités des gestionnaires de pharmacie des ESPC · Formuler des recommandations | E26: DS DIVO; DS DABOU; DS DOROPO et DS Alépé | F26: 01 au 12/06/2026 | G26: ❌ NON | H26: DS DIVO (date pas encore communiquée); DS DABOU (date pas encore communiquée) DS DOROPO (date pas encore communiquée) et DS Alépé (prévue le 29/05/2026; reprogrammée à une date ultérieure pour conflit de calendrier)
A27: 3 | B27: 1.3-2 | C27: 1.3-2.4 : Organiser des rencontres d'orientation logistique au niveau départemental | D27: · Présenter et analyser les résultats des activités logistiques au niveau des ESPC des trois derniers mois (Mars,Avril et MAI): rapportage et qualité des données rapportées ; disponibilités des stocks de produits traceurs et Système d’Alerte Précoce ; Gestion des stocks et utilisation de mSupply ; données de la File Active. · Identifier les problèmes à la mise en œuvre des activités au niveau des ESPC · Renforcer les capacités des gestionnaires de pharmacie des ESPC · Formuler des recommandations | E27: Korhogo 2, Dikodougou, Niakara, Katiola, Botro, Béoumi, Bouaké nord ouest, Mankono, Yamousoukro, Toumodi, Odiénné, Madinani, Zouan-Hounien, Bloléquin, Zoukougbeu, Vavoua, Issia ,Bouaflé, Kani et Kounahiri | F27: 08/06/2026 au 19/06/2026 | G27: ❌ NON | H27: réception des TDR de 08 sites ; préparation avec les Pharmaciens de Districts pour le bon deroulement de ses rencontres
A28: 4 | B28: 1.3-2 | C28: 1.3-2.2 : Organiser des visites d'assistance technique aux acteurs de la chaîne d'approvisionnement décentralisée | D28: effectuer des visites de sites à faibles resultats, travailler avec le site sur:rapportage et qualité des données rapportées ; disponibilités des stocks de produits traceurs et Système d’Alerte Précoce ; Gestion des stocks et utilisation de mSupply ; données de la File Active. | E28: sites à identifier par PRES dans la zone couverte par CAD BOUAKE | F28: du 15/06/26 au 25/06/26 | G28: ❌ NON | H28: identification de sites selon des points précis de mauvaises performance
A29: 5 | B29: 1.3-2 | C29: 1.2-1.1 : Faire le suivi la complétude et la promptitude des rapports des sites non clients directs (mSupply, …) | D29: Assister les sites au rapportage ,dans les délais, des sites clients directs NPSP | E29: sites CAD Bouaké | F29: du 11/05/26 au 31/05/26 | G29: ❌ NON | H29: Disponibilité à 100% des données logistiques pour la prise de décision
A30: 6 | B30: 1.3-1 | C30: 1.3-1.2 : Fournir des forfaits de communication et de connexion internet aux structures du niveau central jusqu'au niveau communautaire. | D30: maintenir les sites clients directs NPSP dans la flotte pour faciliter la communication | E30: CAD Bouaké | F30: en continue | G30: ❌ NON | H30: Maintien de tous les numéros des sites dans la flotte compte tenu du turn over des gestionnaires
A31: 7 | B31: 1.2-1 | C31: 1.4-1.3 : Apporter un appui technique et financier au district sanitaire pour le suivi de la distribution communautaire | D31: Renforcer la disponibilité des CTA et autres ILP en vue d’une meilleure performance de l’ICCM au niveau communautaire | E31: CAD Abidjan | F31: Du 11/05/2026 au 31/05/2026 | G31: ❌ NON | H31: Appui technique à l'élaboration des TDR et à la programmation des visites des DS
A32: 8 | B32: 1.8-2 | C32: 1.8-2.1 : Organiser des sessions de formation des acteurs de la chaîne d'approvisionnement | D32: Renforcer less capacité techniques des gestionnaires (APGP, IDE et SFDE) des produits de santé des sites péripheriques | E32: Yamoussoukro | F32: 01/06/26 au 06/06/26 | G32: ❌ NON | H32: Formation de 30 acteurs (APGP,IDE, SFDE) attendus; des Tests prévus; briefing des formateurs afin de prendre en compte les leçons apprises de la formation du groupe precédant
A33: 9 | B33: 1.2-1 | C33: 1.2-1.1 : Faire le suivi la complétude et la promptitude des rapports des sites non clients directs (mSupply, …) | D33: améliorer le rapportage des sites périphériques | E33: CAD Bouaké | F33: Du 18 au 31/05/2026 | G33: ❌ NON | H33: sensibiliser les gestionnaires sur la gestion des produits périmés afin d'eviter de les rapportés comme produits disponibles et utilisables
A34: 10 | B34: 1.3-2 | C34: 1.3-2.7 : Organiser une orientation des pharmaciens de régions sur le management de la CA | D34: Renforcer les compétence en management et en leadership des PR pour assurer la gouvernance efficace et une redevabilité accrue de la chaine d'approvisionnement pharmaceutique décentralisée | E34: YAMOUSOUKRO | F34: 08 au 12/06/2026 | G34: ❌ NON | H34: Elaboration des plan de contingence des 10 régions participants afin d'améliorer la disponibilité des produits de santé dans leurs points de prestations de service. Partage d'expériences et de bonnes pratiques de gestion de chaine d'approvisionnement
A35: ↳ Toute activité impliquant le DoS doit être transmise au moins 2 semaines avant son démarrage.
A37: D. POINTS DE VIGILANCE / RISQUES / BESOINS DE DÉCISION
A38: ℹ️ Signaler tout élément nécessitant une attention particulière, une décision ou un arbitrage.
A39: N° | B39: Thème | C39: Catégorie | D39: Description du point | E39: Niveau de criticité | F39: Action attendue / Décision souhaitée
A40: 1
A41: 2
A42: 3
A43: 4
A44: 5

Sheet CAC
A1: BULLETIN HEBDOMADAIRE LHSPLA-TA — CANEVAS DE REPORTING ENTITÉ
A2: Entité : CAC - Chaine d'Approvisionnement Communautaire
A4: A. INFORMATIONS DE SOUMISSION
A5: Entité | C5: Responsable (Nom & Prénom) | E5: Semaine de référence | G5: Date de soumission
A6: CAC | E6: =SE!E6 -> Du 25/05 au 29/05/2026 | G6: =SE!G6 -> 46174
A8: B. ACTIVITÉS RÉALISÉES — Semaine précédente
A9: ℹ️ Pour chaque activité réalisée au cours de la semaine écoulée, compléter une ligne.
A10: N° | B10: N° Activités | C10: Libellé de la tâche | D10: Objectifs | E10: Lieu | F10: Date(s) | G10: Principales recommandations / Résultats clés
A11: 1 | B11: 1.4-1 | C11: 1.4-1.4 : Faire le suivi de la disponibilité des produits de santé communautaires | D11: Mission de suivi des recommandations EUV et de coaching des CAC et ASS dans les districts Tiassalé, 2 ESPC 5DR Ahoara et CSU Morokro) caoching au remplissage du registre ASC et au Weekly Report Communautaire. Diffusion du Weekly aux ASS et CAC. | E11: DS TIASSALE | F11: Du 28 au 29 Mai 2026 | G11: Continuer le coaching au rapportage et au remplissage correcte du rapport ASC dans e-SIGL
A12: 2 | B12: 2.2-3 | C12: 2.2-3.1 : Organiser 3 inventaires des produits traceurs des programmes suivis | D12: Réalisation de l'inventaire tournant à l'agence programme du 30 au 31 Mai 2026 | E12: Agence programme | F12: du 16 au 20 Mai 2026 | G12: Inventaire physique réalisé, finalisation de la justification des écarts et de la redaction du rapport en cours
A13: 3
A14: 4
A15: 5
A16: 6
A17: 7
A18: 8
A19: ↳ Ajouter autant de lignes que nécessaire avant soumission.
A21: C. ACTIVITÉS PLANIFIÉES — Mois glissant (4 semaines à venir)
A22: ℹ️ Lister toutes les activités prévues sur les 4 prochaines semaines. Signaler en ROUGE les activités nécessitant la participation du DoS.
A23: N° | B23: N° Activités | C23: Libellé de la tâche | D23: Objectifs | E23: Lieu | F23: Date(s) prévues | G23: Participation DoS ? | H23: Observations / Points d'attention
A24: 1
A25: 2
A26: 3
A27: 4
A28: 5
A29: 6
A30: 7
A31: 8
A32: 9
A33: 10
A34: ↳ Toute activité impliquant le DoS doit être transmise au moins 2 semaines avant son démarrage.
A36: D. POINTS DE VIGILANCE / RISQUES / BESOINS DE DÉCISION
A37: ℹ️ Signaler tout élément nécessitant une attention particulière, une décision ou un arbitrage.
A38: N° | B38: Thème | C38: Catégorie | D38: Description du point | E38: Niveau de criticité | F38: Action attendue / Décision souhaitée
A39: 1
A40: 2
A41: 3
A42: 4
A43: 5

Sheet PMO
A1: BULLETIN HEBDOMADAIRE LHSPLA-TA — CANEVAS DE REPORTING ENTITÉ
A2: Entité : PMO – Gestion de Projet (Project Management Office)
A4: A. INFORMATIONS DE SOUMISSION
A5: Entité | C5: Responsable (Nom & Prénom) | E5: Semaine de référence | G5: Date de soumission
A6: PMO | C6: PILLAH AUDREY | E6: =SE!E6 -> Du 25/05 au 29/05/2026 | G6: =SE!G6 -> 46174
A8: B. ACTIVITÉS RÉALISÉES — Semaine précédente
A9: ℹ️ Pour chaque activité réalisée au cours de la semaine écoulée, compléter une ligne.
A10: N° | B10: N° Activités | C10: Libellé de la tâche | D10: Objectifs | E10: Lieu | F10: Date(s) | G10: Principales recommandations / Résultats clés
A11: 1
A12: 2
A13: 3
A14: 4
A15: 5
A16: 6
A17: 7
A18: 8
A19: ↳ Ajouter autant de lignes que nécessaire avant soumission.
A21: C. ACTIVITÉS PLANIFIÉES — Mois glissant (4 semaines à venir)
A22: ℹ️ Lister toutes les activités prévues sur les 4 prochaines semaines. Signaler en ROUGE les activités nécessitant la participation du DoS.
A23: N° | B23: N° Activités | C23: Libellé de la tâche | D23: Objectifs | E23: Lieu | F23: Date(s) prévues | G23: Participation DoS ? | H23: Observations / Points d'attention
A24: 1 | B24: 1.11-3 | C24: 1.11-3.2 : Organiser des réunions mensuelles du bilan de la performance du projet | D24: Faire le reporting détaillé des activités du projet sur le mois précédent par acteur | E24: Abidjan Nouvelle PSP-CI | F24: 46189 | G24: ❌ NON | H24: *Réunion mois de juin 2026 *Causes de la non-réalisation des activités *Résolution des insatisfactions
A25: 2 | B25: 1.11-4 | C25: 1.11-4.1 : Faire la maintenance annuelle ORCHESTRA | D25: Maintenance annuelle et assistance pour le logiciel de suivi du projet LHSPLA | E25: Abidjan Nouvelle PSP-CI | G25: ❌ NON | H25: *Aucune suite pour le paiement de la maintenance *Risque de bugs lors d'utilisation de Orchestra
A26: 3 | B26: 1.8-3 | C26: 1.8-3.1 : Appuyer les gestionnaires des structures sanitaires publiques dans le cadre de leurs activités | D26: Amélioration des compétences du pool de formateurs pour des formations et des coachings de qualité fait à l'endroit des gestionnaires des structures sanitaires publiques | E26: Yamoussoukro | F26: Date à définir | G26: ❌ NON | H26: Apprentissage de l'andragogie. en deux phases : phase pratique et phase théorique
A27: 4 | B27: 1.11-3 | C27: 1.11-3.1 : Compiler mensuellement les rapports de progression dans le logiciel ORCHESTRA | D27: Orchestra est à jour | E27: Abidjan Nouvelle PSP-CI | F27: du 04 au 05/06/2026 | G27: ❌ NON | H27: Extraction des niveaux d'avancement par entité et transmission des extractions à chaque entité
A28: 5
A29: 6
A30: 7
A31: 8
A32: 9
A33: 10
A34: ↳ Toute activité impliquant le DoS doit être transmise au moins 2 semaines avant son démarrage.
A36: D. POINTS DE VIGILANCE / RISQUES / BESOINS DE DÉCISION
A37: ℹ️ Signaler tout élément nécessitant une attention particulière, une décision ou un arbitrage.
A38: N° | B38: Thème | C38: Catégorie | D38: Description du point | E38: Niveau de criticité | F38: Action attendue / Décision souhaitée
A39: 1 | B39: Gestion de Projet | D39: Restructuration du prestataire du logiciel ORCHESTRA demandant une revision du contrat. Aucune avancée sur le contrat, ce qui retarde la mise en oeuvre du paiement dans le cadre de la maintenance. | E39: 🟠 Élevé | F39: Approche du Département Juridique pour une accélération du traitement de ce dossier.
A40: 2
A41: 3
A42: 4
A43: 5

Sheet QAD
A1: BULLETIN HEBDOMADAIRE LHSPLA-TA — CANEVAS DE REPORTING ENTITÉ
A2: Entité : QAD – Quantifiction Achat et Distribution
A4: A. INFORMATIONS DE SOUMISSION
A5: Entité | C5: Responsable (Nom & Prénom) | E5: Semaine de référence | G5: Date de soumission
A6: QAD | C6: ZILLE CYRILLE | E6: =SE!E6 -> Du 25/05 au 29/05/2026 | G6: =SE!G6 -> 46174
A8: B. ACTIVITÉS RÉALISÉES — Semaine précédente
A9: ℹ️ Pour chaque activité réalisée au cours de la semaine écoulée, compléter une ligne.
A10: N° | B10: N° Activités | C10: Libellé de la tâche | D10: Objectifs | E10: Lieu | F10: Date(s) | G10: Principales recommandations / Résultats clés
A11: 1 | B11: 1.10-1 | C11: 1.10-1.1 : Participer aux réunions de suivi mensuel de stock des PNS | D11: * Suivi mensuel des stocks et des PA pour une disponibilité adéquate des produits à tous les niveaux de la chaine d'approvisionnement pour réduire les risques de rupture et de péremption | E11: En ligne | F11: 46168 | G11: *Principales recommandations pour la NPSP* Fournir la date probable de livraison du reliquat des produits de prémière ligne sous BGE Actualiser le eSigl et le fichier suivi de stock en y rétirant l'amikacine inj Retarder la prochaine commande de Bedaquiline 20mg du fait du surstock observé au niveau central comme péripherique sur ce produit ( fin septembre au lieu de fin juin 2026)
A12: 2 | B12: 3.2-1 | C12: 3.2-1.2 : Mettre à disposition des transitaires la documentation requise pour organiser l'acheminement | D12: * Disponibilité rapide des produits dans les entrepôts NPSP | E12: ABIDJAN | F12: 46171 | G12: * Résultats clés* Transmission des observations (date d'effet) sur le document projet d'exonération sur les acquisitions planifiées sur budget du Gouvernement Américain
A13: 3 | B13: 2.6-5 | C13: 2.6-5.9 : Organiser quatre sessions d'orientation des Acteurs de la gestion logistique | D13: Renforcer les capacités des gestionnaires et techniciens de laboratoire en gestion logistique des produits de la charge virale | E13: ABIDJAN | F13: 46170 | G13: Renforcement des capacités de 18 personnes (pharmacie et laboratoire) sur la gestion des produits de mPima et des consommables généraux relatifs aux produits de laboratoire.
A14: 4 | B14: 2.2-1 | C14: 2.2-1.4 : Mettre en place un fichier de suivi intégré de la reception des produits à la levée de quarantaine de ces produits | D14: Respect des délais objectivés | E14: Abidjan | F14: 25 au 29 mai | G14: Finaliser la correspondance entre les désignation/code QAT et Sage X3 pour transmission interne
A15: 5 | B15: 2.2-3 | C15: 2.2-3.1 : Organiser 3 inventaires des produits traceurs des programmes suivis | D15: Améliorer la précision et la justesse des stocks | E15: Abidjan | F15: 30 mai au 03 juin | G15: Améliorer la communication interne concernant l'inventaire tournant.
A16: 6 | B16: 2.2-2 | C16: 2.2-2.2 : Faire le suivi hebdomadaire de l'exécution du plan de réapprovisionnement | D16: Améliorer la disponibilité des produits dans les agences de distribution | E16: Abidjan | F16: 25 au 31 mai | G16: Aborder ce point lors des prochaines réunions avec les parties prenantes car les délais objectivés sont difficilement attteints
A17: 7 | B17: 2.2-3 | C17: 2.2-3.2 : Faire le suivi de la prise en compte des écarts relevés lors de chaque inventaire | D17: Améliorer la précision et la justesse des stocks | E17: Abidjan | F17: 25 au 31 mai
A18: 8
A19: ↳ Ajouter autant de lignes que nécessaire avant soumission.
A21: C. ACTIVITÉS PLANIFIÉES — Mois glissant (4 semaines à venir)
A22: ℹ️ Lister toutes les activités prévues sur les 4 prochaines semaines. Signaler en ROUGE les activités nécessitant la participation du DoS.
A23: N° | B23: N° Activités | C23: Libellé de la tâche | D23: Objectifs | E23: Lieu | F23: Date(s) prévues | G23: Participation DoS ? | H23: Observations / Points d'attention
A24: 1 | B24: 1.1-6 | C24: 1.1-6.1 : Apporter une assistance technique pour l'organisation d'un atelier de préquantification des médicaments pour la prise en charge de la santé de la Mère et de l'enfant. | D24: Disponibilité des données et hypothèses nécessaires à la prévision des besoins en médicaments de la santé de la mère et de l'enfant | E24: Bassam | F24: 01 au 04 juin 2026 | G24: ✅ OUI
A25: 2 | B25: 1.1-6 | C25: 1.1-6.2 : Apporter une assistance technique pour l'organisation d'un atelier de quantification des médicaments pour la prise en charge de la santé de la Mère et de l'enfant. | D25: Disponibilité des plans d'approvisionnements pour les besoins de la période 2027-2028 | E25: Yamoussoukro | F25: 15 au 20 juin 2026 | G25: ✅ OUI
A26: 3 | B26: 2.6-5 | C26: 2.6-5.2 : Réaliser trois missions de supervision pour les laboratoires de charge virale | D26: Renforcement des capacités des gestionnaires de pharmacie et des techniciens de laboratoire dans la gestion des produits de la charge virale /EID | E26: KORHOGO-BOUAKE-DALOA | F26: 07 au 13 juin 2026 | G26: ❌ NON
B27: 2.6-5 | C27: 2.6-5.9 : Organiser quatre sessions d'orientation des Acteurs de la gestion logistique | D27: Renforcement des capacités des gestionnaires de pharmacie et des techniciens de laboratoire dans la gestion des produits de la charge virale /EID | E27: ABIDJAN | F27: 01-04 juin 2026 | G27: ❌ NON
A28: 5 | B28: 2.6-5 | C28: 2.6-5.2 : Réaliser trois missions de supervision pour les laboratoires de charge virale | D28: Renforcement des capacités des gestionnaires de pharmacie et des techniciens de laboratoire dans la gestion des produits de la charge virale /EID | E28: ABENGOUROU | F28: 17 au 19 juin 2026 | G28: ❌ NON
A29: 6 | B29: 2.2-1 | C29: 2.2-1.2 : Faire un suivi hebdomadaire des entrées en machine des produits de programme | D29: Améliorer la disponibilité des produits au niveau des Agences de distribution | E29: Abidjan | F29: 25 au 31 mai | G29: ❌ NON
A30: 7 | B30: 2.2-3 | C30: 2.2-3.2 : Faire le suivi de la prise en compte des écarts relevés lors de chaque inventaire | D30: Améliorer la précision et la justesse des stocks | E30: Abidjan | F30: 25 au 31 mai | G30: ❌ NON
A31: 8 | B31: 2.2-2 | C31: 2.2-2.2 : Faire le suivi hebdomadaire de l'exécution du plan de réapprovisionnement | D31: Améliorer la disponibilité des produits dans les agences de distribution | E31: Abidjan | F31: 25 au 31 mai | G31: ❌ NON
A32: 9 | B32: 2.6-2 | C32: 2.6-2.1 : Organiser des reunions quinzomadaires de suivi des performances de l'Agence Programme | D32: Améliorer la disponibité et la distribution des produits des programmes aux sites clients directs | E32: Abidjan | F32: 25 mai au 7 juin | G32: ❌ NON
A33: 10 | B33: 2.2-1 | C33: 2.2-1.4 : Mettre en place un fichier de suivi intégré de la reception des produits à la levée de quarantaine de ces produits | D33: Respect des délais objectivés | E33: Abidjan | F33: 25 mai au 7 juin | G33: ❌ NON
A34: ↳ Toute activité impliquant le DoS doit être transmise au moins 2 semaines avant son démarrage.
A36: D. POINTS DE VIGILANCE / RISQUES / BESOINS DE DÉCISION
A37: ℹ️ Signaler tout élément nécessitant une attention particulière, une décision ou un arbitrage.
A38: N° | B38: Thème | C38: Catégorie | D38: Description du point | E38: Niveau de criticité | F38: Action attendue / Décision souhaitée
A39: 1 | B39: Commandes et Approvisionnement | C39: Traitement de commandes fournisseurs | D39: Faible disponibilité de plusieurs consommables à acquerir sur budget ETAT au niveau central (DBS, Tubes EDTA, Tubes rouge, Tubes gris, Pastilles de chloramine, etc) | E39: 🟠 Élevé | F39: - Procéder à des acquisitions de dépannages pour garantir la continuité des services - Procéder au paiement des fournisseurs pour une livraison des kits DBS
A40: 2 | B40: Commandes et Approvisionnement | C40: Dédouanement et enlèvement | D40: Refus de libération des colis arrivés en raison de l'expiration de l'exonération des produits financés par le Gouvernement Américain. Le service Transit a indiqué que la douane réclamait un courrier, une note ou un document officiel indiquant la poursuite des activités du projet LHSPLA sous le couvert du Département d'Etat Américain. | E40: 🟠 Élevé | F40: - Obtenir un délai additionnel avec la DGD pour la libération des colis arrivés en attendant le renouvellement de l'exonération des produits acquis sur le budget du Gouvernement Américain
A41: 3
A42: 4
A43: 5
A45: LHSPLA-TA | NPSP-CI | Canevas préparé par Charles Oscar LEBRI, MEL Manager | FY2026

Sheet SE
A1: BULLETIN HEBDOMADAIRE LHSPLA-TA — CANEVAS DE REPORTING ENTITÉ
A2: Entité : SE – Suivi & Évaluation (MEL)
A4: A. INFORMATIONS DE SOUMISSION
A5: Entité | C5: Responsable (Nom & Prénom) | E5: Semaine de référence | G5: Date de soumission
A6: SE | C6: LEBRI Charles Oscar | E6: Du 25/05 au 29/05/2026 | G6: 46174
A8: B. ACTIVITÉS RÉALISÉES — Semaine précédente
A9: ℹ️ Pour chaque activité réalisée au cours de la semaine écoulée, compléter une ligne.
A10: N° | B10: N° Activités | C10: Libellé de la tâche | D10: Objectifs | E10: Lieu | F10: Date(s) | G10: Principales recommandations / Résultats clés
A11: 3
A12: 4
A13: 5
A14: 6
A15: 7
A16: 8
A17: ↳ Ajouter autant de lignes que nécessaire avant soumission.
A19: C. ACTIVITÉS PLANIFIÉES — Mois glissant (4 semaines à venir)
A20: ℹ️ Lister toutes les activités prévues sur les 4 prochaines semaines. Signaler en ROUGE les activités nécessitant la participation du DoS.
A21: N° | B21: N° Activités | C21: Libellé de la tâche | D21: Objectifs | E21: Lieu | F21: Date(s) prévues | G21: Participation DoS ? | H21: Observations / Points d'attention
A22: 2 | B22: 1.7-6 | C22: 1.7-6.5 : Apporter un appui à la mise en oeuvre des recommandations de l'EUV. | D22: Évaluer le niveau de mise en œuvre des recommandations issues de l'EUV 2025 et renforcer les capacités des agents de la chaîne d'approvisionnement dans la gestion des produits antipaludiques au niveau de 10 districts sanitaires identifiés. | E22: MARAHOUE, HAMBOL, GBEKE, LOH-GUIBOUA, IFFOU, AGNEBY-TIASSA | F22: 27/05/2026 au 10/06/2026 | G22: ❌ NON
A23: 3 | B23: 1.7-3 | C23: 1.7-3.4 : Déploiement dans 31 régions | D23: Déployer et Former les gestionnaires des établissements sanitaires, en charge de la File Active dans les districts sanitaires des régions de BOUNKANI, GBOKLE, NAWA, GUEMON, HAUT-SASSANDRA, HAMBOL et GÔH, à l’utilisation du SNGFA pour le rapportage et la gestion des données de file active | E23: AGNEBY-TIASSA, N'ZI, MARAHOUE, GOH, GUEMON et HAMBOL | F23: 07/06/2026 au 18/06/2026 | G23: ❌ NON | H23: Quelques ajustements mineurs de l'outil, relatifs aux formulaires de suivi des patients, ont été identifiés et communiqués à Bluesquare par l'équipe LHSPLA.
A24: 4 | B24: 1.7-3 | C24: 1.7-3.4 : Déploiement dans 31 régions | D24: Déployer et Former les gestionnaires des établissements sanitaires, en charge de la File Active dans les districts sanitaires des régions de LOH DJIBOUA, MORONOU,IFFOU, BAGOUE, GRANDS-PONTS et BAFING, à l’utilisation du SNGFA pour le rapportage et la gestion des données de file active | E24: LOH DJIBOUA ; MORONOU ; IFFOU ; BAGOUE ; GRANDS-PONTS et BAFING | F24: 21/06/2026 au 03/07/2026 | G24: ❌ NON
A25: 5
A26: 6
A27: 7
A28: 8
A29: 9
A30: 10
A31: ↳ Toute activité impliquant le DoS doit être transmise au moins 2 semaines avant son démarrage.
A33: D. POINTS DE VIGILANCE / RISQUES / BESOINS DE DÉCISION
A34: ℹ️ Signaler tout élément nécessitant une attention particulière, une décision ou un arbitrage.
A35: N° | B35: Thème | C35: Catégorie | D35: Description du point | E35: Niveau de criticité | F35: Action attendue / Décision souhaitée
A36: 1
A37: 2
A38: 3
A39: 4
A40: 5

Sheet SI
A1: BULLETIN HEBDOMADAIRE LHSPLA-TA — CANEVAS DE REPORTING ENTITÉ
A2: Entité : SI – Système d'Information
A4: A. INFORMATIONS DE SOUMISSION
A5: Entité | C5: Responsable (Nom & Prénom) | E5: Semaine de référence | G5: Date de soumission
A6: SI | C6: KOUAKOU ABIMAN THERESE D'AVILA EPSE DJEREKE | E6: =SE!E6 -> Du 25/05 au 29/05/2026 | G6: =SE!G6 -> 46174
A8: B. ACTIVITÉS RÉALISÉES — Semaine précédente
A9: ℹ️ Pour chaque activité réalisée au cours de la semaine écoulée, compléter une ligne.
A10: N° | B10: N° Activités | C10: Libellé de la tâche | D10: Objectifs | E10: Lieu | F10: Date(s) | G10: Principales recommandations / Résultats clés
A11: 1
A12: 2
A13: 3
A14: 4
A15: 5
A16: 6
A17: 7
A18: 8
A19: ↳ Ajouter autant de lignes que nécessaire avant soumission.
A21: C. ACTIVITÉS PLANIFIÉES — Mois glissant (4 semaines à venir)
A22: ℹ️ Lister toutes les activités prévues sur les 4 prochaines semaines. Signaler en ROUGE les activités nécessitant la participation du DoS.
A23: N° | B23: N° Activités | C23: Libellé de la tâche | D23: Objectifs | E23: Lieu | F23: Date(s) prévues | G23: Participation DoS ? | H23: Observations / Points d'attention
A24: 4 | B24: 4.2-3 | C24: 4.2.3.3 : Développer des guides utilisateurs simplifiés | D24: - Ciblage précis des besoins en formations ; - éviter les sessions génériques peu efficaces - optimiser le budget | F24: du 01/06/2026 au 31/06/2026 | G24: ❌ NON
A25: 5 | B25: 1.2-3 | C25: 1.2-3.1 : Equiper la NPSP en équipement informatique | D25: Doter la NPSP d’ordinateurs portables | F25: du 01/06/2026 au 31/06/2026 | G25: ❌ NON | H25: Acquisition prévu: 37 ordinateurs Une premiere acquisition de 14 ordinateurs est en cours; Reste 23 ordinateurs à aquérir
A26: 6 | B26: 4.2-5 | C26: 4.2.5.1 : Réaliser une évaluation diagnostique initial (Data Quality Assessment) | D26: - Mesurer l’exactitude des données (concordance entre les données saisies et les sources primaires). - Évaluer l’exhaustivité (complétude des enregistrements et des rapports). - Vérifier la ponctualité (respect des délais de saisie et de transmission). - Analyser la cohérence des données (absence de contradictions entre les différentes sources et rapports). - Apprécier l’accessibilité des données (facilité d’accès, disponibilité et utilisation pour la prise de décision). | E26: Les districts sanitaires de Bondoukou, Kani, Niakaramadougou, Sandegué, Yakassé Attobrou, Gagnoa 1, Daloa, Bouafé, Fresco, Dianra | F26: du 08/06/2026 au 12/06/2026 | G26: ❌ NON
A27: 7 | B27: 4.2-5 | C27: 4.2.5.4 : Monitorer à distance les sites identifiés par le DQA – tableau de bord mSupply | D27: - Suivre en temps réel les indicateurs clés de performance des sites sélectionnés. - Identifier rapidement les anomalies, incohérences et écarts de données. - Évaluer la qualité et la complétude des données saisies dans mSupply. - Détecter les sites nécessitant un accompagnement ou des actions correctives. - Produire des rapports périodiques de suivi à destination des parties prenantes. - Faciliter la prise de décision basée sur les données issues du tableau de bord mSupply. | F27: du 15/06/2026 au 27/06/2026 | G27: ❌ NON
A28: 8 | B28: 4.2-4 | C28: 4.2.4.1 : Cartographier et prioriser les bugs mSupply | D28: - Recenser et documenter tous les bugs signalés dans mSupply. - Classifier les anomalies par module, fonctionnalité et type d'incident. - Évaluer l'impact de chaque bug sur les opérations et les utilisateurs. - Définir les niveaux de priorité (critique, majeur, mineur, faible). - Élaborer une feuille de route de correction en collaboration avec les équipes techniques et métiers. - Assurer le suivi de la résolution des anomalies jusqu'à leur clôture. | F28: du 01/06/2026 au 31/06/2026 | G28: ❌ NON
A29: 9
A30: 10
A31: ↳ Toute activité impliquant le DoS doit être transmise au moins 2 semaines avant son démarrage.
A33: D. POINTS DE VIGILANCE / RISQUES / BESOINS DE DÉCISION
A34: ℹ️ Signaler tout élément nécessitant une attention particulière, une décision ou un arbitrage.
A35: N° | B35: Thème | C35: Catégorie | D35: Description du point | E35: Niveau de criticité | F35: Action attendue / Décision souhaitée
A36: 1
A37: 2
A38: 3
A39: 4
A40: 5
A42: LHSPLA-TA | NPSP-CI | Canevas préparé par Charles Oscar LEBRI, MEL Manager | FY2026

Sheet FINANCES
A1: BULLETIN HEBDOMADAIRE LHSPLA-TA — CANEVAS DE REPORTING ENTITÉ
A2: Entité : Service Finances
A4: A. INFORMATIONS DE SOUMISSION
A5: Entité / Unité | C5: Responsable (Nom & Prénom) | E5: Semaine de référence | G5: Date de soumission
A6: FINANCES | C6: YAPO ARNAUD | E6: Du 24/04 au 01/05/2026 | G6: 46168
A8: B. ACTIVITÉS RÉALISÉES — Semaine précédente
A9: ℹ️ Pour chaque activité réalisée au cours de la semaine écoulée, compléter une ligne.
A10: N° | B10: N° Activités | C10: Libellé de la tâche | D10: Objectifs | E10: Lieu | F10: Date(s) | G10: Principales recommandations / Résultats clés
A11: 1 | B11: 1.11-1 | C11: 1.11-1.12 : Acquisition de stickers pour le matériel acquis par le projet | D11: Référencer et identifier le matériel acquis dans le cadre du projet LHSPLA | E11: Abidjan | F11: 46164 | G11: Finaliser les code QR
A12: 2 | B12: 1.11-1 | C12: 1.11-1.11 : Equiper le personnel du projet en matériel informatique | D12: Renforcer les capacités opérationnelles et le système d'information de l’équipe projet LHSPLA | E12: Abidjan | F12: 46164 | G12: Finaliser le paiement d'un acompte au fournisseur.
A13: 3 | B13: 1.11-1 | C13: 1.11-1.9 : Rémunération des agents LHSPLA. | D13: Déterminer la quote part de chaque financement dans les refacturation de salaires d'avril à septembre 2026 | E13: Abidjan | F13: 46155 | G13: Proposition de quote part COP=49% MOP=19% MCH=32%
A14: 4 | B14: 1.11-1 | C14: 1.11-1.5 : Atelier de formation sur les méthodes de réconciliations des pièces comptables | D14: Création d'un outil permettant de générer des budgets de TDR | E14: Abidjan | F14: 46164 | G14: Cahier de charge transmis au SI Vidéo demonstrative effectuée Test de l'outil
A15: 5 | B15: 1.11-1 | C15: 1.11-1.2 : Réaliser des clôtures comptables mensuels | D15: Editer les liquidations d'octobre 2025 à Avril 2026 pour approbation | E15: Abidjan | F15: 46162 | G15: Raport financier présentant les charges et les dépenses effectuées de la période
A16: 6 | B16: 1.11-1 | C16: 1.11-1.2 : Réaliser des clôtures comptables mensuels | D16: Editer les appels de fonds de juin à septembre 2026 pour approbation | E16: Abidjan | F16: 46162 | G16: Appels de fonds de juin à septembre 2026
A17: 7
A18: 8
A19: ↳ Ajouter autant de lignes que nécessaire avant soumission.
A21: C. ACTIVITÉS PLANIFIÉES — Mois glissant (4 semaines à venir)
A22: ℹ️ Lister toutes les activités prévues sur les 4 prochaines semaines. Signaler en ROUGE les activités nécessitant la participation du DoS.
A23: N° | B23: N° Activités | C23: Libellé de la tâche | D23: Objectifs | E23: Lieu | F23: Date(s) prévues | G23: Participation DoS ? | H23: Observations / Points d'attention
A24: 1 | B24: 1.11-1 | C24: 1.11-1.2 : Réaliser des clôtures comptables mensuels | D24: Produire des états financiers fiables présentant la situation financière du projet à fin avril 2026 | E24: NPSP | F24: 46164 | G24: ❌ NON | H24: CONTRÔLE DES COMPTES CLES: Charges, produits, tiers
A25: 2 | B25: 1.11-1 | C25: 1.11-1.3 : Réaliser un audit interne | D25: Préparer l'audit financier du projet LHSPLA de l'exercice 2025 | E25: NPSP | F25: 46174 | G25: ❌ NON | H25: L'activité sera effectué avec un cabinet
A26: 3 | B26: 1.11-1 | C26: 1.11-1.1 : Organiser une mission de collecte et de réconciliation des pièces sur le terrain | D26: Collecter les pièces et finaliser les reconciliations des appuis aux sites décentralisés | E26: NPSP | F26: 46174 | G26: ❌ NON
A27: 4
A28: 5
A29: 6
A30: 7
A31: 8
A32: 9
A33: 10
A34: ↳ Toute activité impliquant le DoS doit être transmise au moins 2 semaines avant son démarrage.
A36: D. POINTS DE VIGILANCE / RISQUES / BESOINS DE DÉCISION
A37: ℹ️ Signaler tout élément nécessitant une attention particulière, une décision ou un arbitrage.
A38: N° | B38: Thème | C38: Catégorie | D38: Description du point | E38: Niveau de criticité | F38: Action attendue / Décision souhaitée
A39: 1
A40: 2
A41: 3
A42: 4
A43: 5

Sheet COM
A1: BULLETIN HEBDOMADAIRE LHSPLA-TA — CANEVAS DE REPORTING ENTITÉ
A2: Entité : Service Communication
A4: A. INFORMATIONS DE SOUMISSION
A5: Entité | C5: Responsable (Nom & Prénom) | E5: Semaine de référence | G5: Date de soumission
A6: COM | E6: =SE!E6 -> Du 25/05 au 29/05/2026 | G6: =SE!G6 -> 46174
A8: B. ACTIVITÉS RÉALISÉES — Semaine précédente
A9: ℹ️ Pour chaque activité réalisée au cours de la semaine écoulée, compléter une ligne.
A10: N° | B10: N° Activités | C10: Libellé de la tâche | D10: Objectifs | E10: Lieu | F10: Date(s) | G10: Principales recommandations / Résultats clés
A11: 1
A12: 2
A13: 3
A14: 4
A15: 5
A16: 6
A17: 7
A18: 8
A19: ↳ Ajouter autant de lignes que nécessaire avant soumission.
A21: C. ACTIVITÉS PLANIFIÉES — Mois glissant (4 semaines à venir)
A22: ℹ️ Lister toutes les activités prévues sur les 4 prochaines semaines. Signaler en ROUGE les activités nécessitant la participation du DoS.
A23: N° | B23: N° Activités | C23: Libellé de la tâche | D23: Objectifs | E23: Lieu | F23: Date(s) prévues | G23: Participation DoS ? | H23: Observations / Points d'attention
A24: 1
A25: 2
A26: 3
A27: 4
A28: 5
A29: 6
A30: 7
A31: 8
A32: 9
A33: 10
A34: ↳ Toute activité impliquant le DoS doit être transmise au moins 2 semaines avant son démarrage.
A36: D. POINTS DE VIGILANCE / RISQUES / BESOINS DE DÉCISION
A37: ℹ️ Signaler tout élément nécessitant une attention particulière, une décision ou un arbitrage.
A38: N° | B38: Thème | C38: Catégorie | D38: Description du point | E38: Niveau de criticité | F38: Action attendue / Décision souhaitée
A39: 1
A40: 2
A41: 3
A42: 4
A43: 5

Sheet COMPILATION
A1: COMPILATION HEBDOMADAIRE — BULLETIN LHSPLA-TA
A2: Semaine de référence : (se renseigne automatiquement à partir des onglets entité) | E2: Semaine du 27 avril au 01 mai 2026
A4: B. ACTIVITÉS RÉALISÉES — Semaine précédente (toutes entités)
A5: CAD – Chaîne d'Approvisionnement Décentralisée
A6: N° | B6: Titre de l'activité | C6: Objectifs | D6: Lieu | E6: Date(s) | F6: Principales recommandations / Résultats clés
A7: 1 | B7: =IF(CAD!C11="","",CAD!C11) -> 1.3-2.4 : Organiser des rencontres d'orientation logistique au niveau départemental | C7: =IF(CAD!D11="","",CAD!D11) -> · Présenter et analyser les résultats des activités logistiques au niveau des ESPC : rapportage et qualité des données rapportées ; disponibilités des stocks de produits traceurs et Système d’Alerte Précoce ; Gestion des stocks et utilisation de mSupply ; données de la File Active. · Identifier les problèmes à la mise en œuvre des activités au niveau des ESPC · Renforcer les capacités des gestionnaires de pharmacie des ESPC · Formuler des recommandations | D7: =IF(CAD!E11="","",CAD!E11) -> DS APA (26/05/2026) | E7: =IF(CAD!F11="","",CAD!F11) -> 46168 | F7: =IF(CAD!G11="","",CAD!G11) -> Nombre d'acteurs des ESPC présents : 14 acteurs; Les acteurs présents ont été sensibilités sur l'importance du respect du délai de dépôt des RM, coachés sur la qualité des données rapportées en passant en revue les erreurs courantes de rapportage (report mensuel des données; mauvaise unité de rapportage; items insuffisamment renseignés; erreurs de calculs; les incohérences régimes et indicateurs), au SAP et sa mise en oeuvre. Aussi, les acteurs ont été orientés sur la gestion des produits iCCM. Quelques recommandations : Organiser les services en responsabilisant les acteurs; Elaborer et transmettre dans les délais les RM; Valider en interne les données avant transmission des rapports au DS; Utiliser correctement toutes les fonctionnalités de mSupply; Estimer correctement les quantités à allouer en tenant compte des consommations réelles et des nombres de jours de rupture notifiés; Mettre en oeuvre le SAP pour anticiper tous risques de rupture et de péremptione
A8: 2 | B8: =IF(CAD!C12="","",CAD!C12) -> 1.3-2.2 : Organiser des visites d'assistance technique aux acteurs de la chaîne d'approvisionnement décentralisée | C8: =IF(CAD!D12="","",CAD!D12) -> Améliorer la qualité du rapportage, la qualité des prestations et de la gestion des produits et intrants des PNS | D8: =IF(CAD!E12="","",CAD!E12) | E8: =IF(CAD!F12="","",CAD!F12) -> Du 25 au 29/05/2026 | F8: =IF(CAD!G12="","",CAD!G12) -> Pas de visite réalisée cette semaine
A9: 3 | B9: =IF(CAD!C13="","",CAD!C13) -> 1.3-2.3 : Apporter un appui technique et financier aux réunions régionales d'analyse et de mise à niveau des stocks | C9: =IF(CAD!D13="","",CAD!D13) -> Accompagner les gestionnaires des sites clients directs dans l'exécution effective des plans de redéploiements des stocks issus des réunions d'analyse | D9: =IF(CAD!E13="","",CAD!E13) -> Suivi de l'execution des plans de redeploiement élaborés et en cours de réalisation | E9: =IF(CAD!F13="","",CAD!F13) -> Du 25 au 29/05/2026 | F9: =IF(CAD!G13="","",CAD!G13) -> 1 plan de redéploiement a été élaboré et en cours de réalisation avec l'appui logistique de LHSPLA. Pour les réunions réalisées la semaine du 11 au 15/05/202, le point de suivi de la réalisation des 4 plans de redéploiement est le suivant : Région Moronou (100%); Région Lôh Djiboua (80%); Région Gôh (80%) et Agnéby-Tiassa (80%)
A10: 4 | B10: =IF(CAD!C14="","",CAD!C14) -> 1.3-1.1 : Faire la mise à jour mensuelle des contacts téléphoniques des prestataires à insérer dans la flotte | C10: =IF(CAD!D14="","",CAD!D14) -> Faciliter les échanges d'informations logistiques des produits de santé du niveau central au niveau communautaire | D10: =IF(CAD!E14="","",CAD!E14) | E10: =IF(CAD!F14="","",CAD!F14) | F10: =IF(CAD!G14="","",CAD!G14)
A11: 5 | B11: =IF(CAD!C15="","",CAD!C15) -> 1.2-1.1 : Faire le suivi la complétude et la promptitude des rapports des sites non clients directs (mSupply, …) | C11: =IF(CAD!D15="","",CAD!D15) -> améliorer la disponibilité des produits traceurs au niveau des sites derservis par les districts | D11: =IF(CAD!E15="","",CAD!E15) -> Régions sanitaires livrées par l'Agence Régionale de Bouaké | E11: =IF(CAD!F15="","",CAD!F15) -> Du 25/05/2026 au 31/05/2026 | F11: =IF(CAD!G15="","",CAD!G15) -> Relance sous forme de rappels dans les groupes watsapp de districts pour les differentes tâches à effectuer avec mSupply;
A12: 6 | B12: =IF(CAD!C16="","",CAD!C16) -> 1.3-2.3 : Apporter un appui technique et financier aux réunions régionales d'analyse et de mise à niveau des stocks | C12: =IF(CAD!D16="","",CAD!D16) -> améliorer la disponibilité des produits traceurs des programmes de sante au niveau de chaque région | D12: =IF(CAD!E16="","",CAD!E16) -> Bélier, Marahoué,Hambol, Haut-Sassandra, Guémon, et Worodougou | E12: =IF(CAD!F16="","",CAD!F16) -> Du 25/05/2026 au 29/05/2026 | F12: =IF(CAD!G16="","",CAD!G16) -> suivi de l'excécution des plans de rédeploiement issus des réunions d'analyse des stocks; le taux est de 100% pour le Worodougou, Bélier et Haut-Sassandra
A13: 7 | B13: =IF(CAD!C17="","",CAD!C17) -> 1.8-2.1 : Organiser des sessions de formation des acteurs de la chaîne d'approvisionnement | C13: =IF(CAD!D17="","",CAD!D17) -> Renforcer less capacité techniques des gestionnaires (APGP, IDE et SFDE) des produits de santé des sites péripheriques | D13: =IF(CAD!E17="","",CAD!E17) -> Yamoussoukro | E13: =IF(CAD!F17="","",CAD!F17) -> 27/05/2026 au 31/05/2026 | F13: =IF(CAD!G17="","",CAD!G17) -> Formation de 15 acteurs des ESPC et districts surl'optimisation de la gestion des stocks des produits de santé; entreposage et stockage; prise en main de mSupply; Système d'Alerte Précoce et Assistance Technique. La progression des apprenants etait significative à l'issu des pré et Post-Test
A14: 8 | B14: =IF(CAD!C18="","",CAD!C18) | C14: =IF(CAD!D18="","",CAD!D18) | D14: =IF(CAD!E18="","",CAD!E18) | E14: =IF(CAD!F18="","",CAD!F18) | F14: =IF(CAD!G18="","",CAD!G18)
A16: PMO – Gestion de Projet (Project Management Office)
A17: N° | B17: Titre de l'activité | C17: Objectifs | D17: Lieu | E17: Date(s) | F17: Principales recommandations / Résultats clés
A18: 1 | B18: =IF(PMO!C11="","",PMO!C11) | C18: =IF(PMO!D11="","",PMO!D11) | D18: =IF(PMO!E11="","",PMO!E11) | E18: =IF(PMO!F11="","",PMO!F11) | F18: =IF(PMO!G11="","",PMO!G11)
A19: 2 | B19: =IF(PMO!C12="","",PMO!C12) | C19: =IF(PMO!D12="","",PMO!D12) | D19: =IF(PMO!E12="","",PMO!E12) | E19: =IF(PMO!F12="","",PMO!F12) | F19: =IF(PMO!G12="","",PMO!G12)
A20: 3 | B20: =IF(PMO!C13="","",PMO!C13) | C20: =IF(PMO!D13="","",PMO!D13) | D20: =IF(PMO!E13="","",PMO!E13) | E20: =IF(PMO!F13="","",PMO!F13) | F20: =IF(PMO!G13="","",PMO!G13)
A21: 4 | B21: =IF(PMO!C14="","",PMO!C14) | C21: =IF(PMO!D14="","",PMO!D14) | D21: =IF(PMO!E14="","",PMO!E14) | E21: =IF(PMO!F14="","",PMO!F14) | F21: =IF(PMO!G14="","",PMO!G14)
A22: 5 | B22: =IF(PMO!C15="","",PMO!C15) | C22: =IF(PMO!D15="","",PMO!D15) | D22: =IF(PMO!E15="","",PMO!E15) | E22: =IF(PMO!F15="","",PMO!F15) | F22: =IF(PMO!G15="","",PMO!G15)
A23: 6 | B23: =IF(PMO!C16="","",PMO!C16) | C23: =IF(PMO!D16="","",PMO!D16) | D23: =IF(PMO!E16="","",PMO!E16) | E23: =IF(PMO!F16="","",PMO!F16) | F23: =IF(PMO!G16="","",PMO!G16)
A24: 7 | B24: =IF(PMO!C17="","",PMO!C17) | C24: =IF(PMO!D17="","",PMO!D17) | D24: =IF(PMO!E17="","",PMO!E17) | E24: =IF(PMO!F17="","",PMO!F17) | F24: =IF(PMO!G17="","",PMO!G17)
A25: 8 | B25: =IF(PMO!C18="","",PMO!C18) | C25: =IF(PMO!D18="","",PMO!D18) | D25: =IF(PMO!E18="","",PMO!E18) | E25: =IF(PMO!F18="","",PMO!F18) | F25: =IF(PMO!G18="","",PMO!G18)
A27: QAD – Quantifiction Achat et Distribution
A28: N° | B28: Titre de l'activité | C28: Objectifs | D28: Lieu | E28: Date(s) | F28: Principales recommandations / Résultats clés
A29: 1 | B29: =IF(QAD!C11="","",QAD!C11) -> 1.10-1.1 : Participer aux réunions de suivi mensuel de stock des PNS | C29: =IF(QAD!D11="","",QAD!D11) -> * Suivi mensuel des stocks et des PA pour une disponibilité adéquate des produits à tous les niveaux de la chaine d'approvisionnement pour réduire les risques de rupture et de péremption | D29: =IF(QAD!E11="","",QAD!E11) -> En ligne | E29: =IF(QAD!F11="","",QAD!F11) -> 46168 | F29: =IF(QAD!G11="","",QAD!G11) -> *Principales recommandations pour la NPSP* Fournir la date probable de livraison du reliquat des produits de prémière ligne sous BGE Actualiser le eSigl et le fichier suivi de stock en y rétirant l'amikacine inj Retarder la prochaine commande de Bedaquiline 20mg du fait du surstock observé au niveau central comme péripherique sur ce produit ( fin septembre au lieu de fin juin 2026)
A30: 2 | B30: =IF(QAD!C12="","",QAD!C12) -> 3.2-1.2 : Mettre à disposition des transitaires la documentation requise pour organiser l'acheminement | C30: =IF(QAD!D12="","",QAD!D12) -> * Disponibilité rapide des produits dans les entrepôts NPSP | D30: =IF(QAD!E12="","",QAD!E12) -> ABIDJAN | E30: =IF(QAD!F12="","",QAD!F12) -> 46171 | F30: =IF(QAD!G12="","",QAD!G12) -> * Résultats clés* Transmission des observations (date d'effet) sur le document projet d'exonération sur les acquisitions planifiées sur budget du Gouvernement Américain
A31: 3 | B31: =IF(QAD!C13="","",QAD!C13) -> 2.6-5.9 : Organiser quatre sessions d'orientation des Acteurs de la gestion logistique | C31: =IF(QAD!D13="","",QAD!D13) -> Renforcer les capacités des gestionnaires et techniciens de laboratoire en gestion logistique des produits de la charge virale | D31: =IF(QAD!E13="","",QAD!E13) -> ABIDJAN | E31: =IF(QAD!F13="","",QAD!F13) -> 46170 | F31: =IF(QAD!G13="","",QAD!G13) -> Renforcement des capacités de 18 personnes (pharmacie et laboratoire) sur la gestion des produits de mPima et des consommables généraux relatifs aux produits de laboratoire.
A32: 4 | B32: =IF(QAD!C14="","",QAD!C14) -> 2.2-1.4 : Mettre en place un fichier de suivi intégré de la reception des produits à la levée de quarantaine de ces produits | C32: =IF(QAD!D14="","",QAD!D14) -> Respect des délais objectivés | D32: =IF(QAD!E14="","",QAD!E14) -> Abidjan | E32: =IF(QAD!F14="","",QAD!F14) -> 25 au 29 mai | F32: =IF(QAD!G14="","",QAD!G14) -> Finaliser la correspondance entre les désignation/code QAT et Sage X3 pour transmission interne
A33: 5 | B33: =IF(QAD!C15="","",QAD!C15) -> 2.2-3.1 : Organiser 3 inventaires des produits traceurs des programmes suivis | C33: =IF(QAD!D15="","",QAD!D15) -> Améliorer la précision et la justesse des stocks | D33: =IF(QAD!E15="","",QAD!E15) -> Abidjan | E33: =IF(QAD!F15="","",QAD!F15) -> 30 mai au 03 juin | F33: =IF(QAD!G15="","",QAD!G15) -> Améliorer la communication interne concernant l'inventaire tournant.
A34: 6 | B34: =IF(QAD!C16="","",QAD!C16) -> 2.2-2.2 : Faire le suivi hebdomadaire de l'exécution du plan de réapprovisionnement | C34: =IF(QAD!D16="","",QAD!D16) -> Améliorer la disponibilité des produits dans les agences de distribution | D34: =IF(QAD!E16="","",QAD!E16) -> Abidjan | E34: =IF(QAD!F16="","",QAD!F16) -> 25 au 31 mai | F34: =IF(QAD!G16="","",QAD!G16) -> Aborder ce point lors des prochaines réunions avec les parties prenantes car les délais objectivés sont difficilement attteints
A35: 7 | B35: =IF(QAD!C17="","",QAD!C17) -> 2.2-3.2 : Faire le suivi de la prise en compte des écarts relevés lors de chaque inventaire | C35: =IF(QAD!D17="","",QAD!D17) -> Améliorer la précision et la justesse des stocks | D35: =IF(QAD!E17="","",QAD!E17) -> Abidjan | E35: =IF(QAD!F17="","",QAD!F17) -> 25 au 31 mai | F35: =IF(QAD!G17="","",QAD!G17)
A36: 8 | B36: =IF(QAD!C18="","",QAD!C18) | C36: =IF(QAD!D18="","",QAD!D18) | D36: =IF(QAD!E18="","",QAD!E18) | E36: =IF(QAD!F18="","",QAD!F18) | F36: =IF(QAD!G18="","",QAD!G18)
A38: SE – Suivi & Évaluation (MEL)
A39: N° | B39: Titre de l'activité | C39: Objectifs | D39: Lieu | E39: Date(s) | F39: Principales recommandations / Résultats clés
A40: 3 | B40: =IF(SE!C11="","",SE!C11) | C40: =IF(SE!D11="","",SE!D11) | D40: =IF(SE!E11="","",SE!E11) | E40: =IF(SE!F11="","",SE!F11) | F40: =IF(SE!G11="","",SE!G11)
A41: 4 | B41: =IF(SE!C12="","",SE!C12) | C41: =IF(SE!D12="","",SE!D12) | D41: =IF(SE!E12="","",SE!E12) | E41: =IF(SE!F12="","",SE!F12) | F41: =IF(SE!G12="","",SE!G12)
A42: 5 | B42: =IF(SE!C13="","",SE!C13) | C42: =IF(SE!D13="","",SE!D13) | D42: =IF(SE!E13="","",SE!E13) | E42: =IF(SE!F13="","",SE!F13) | F42: =IF(SE!G13="","",SE!G13)
A43: 6 | B43: =IF(SE!C14="","",SE!C14) | C43: =IF(SE!D14="","",SE!D14) | D43: =IF(SE!E14="","",SE!E14) | E43: =IF(SE!F14="","",SE!F14) | F43: =IF(SE!G14="","",SE!G14)
A44: 7 | B44: =IF(SE!C15="","",SE!C15) | C44: =IF(SE!D15="","",SE!D15) | D44: =IF(SE!E15="","",SE!E15) | E44: =IF(SE!F15="","",SE!F15) | F44: =IF(SE!G15="","",SE!G15)
...

Sheet BulletinDu_25-29mai2026
A1: COMPILATION HEBDOMADAIRE — BULLETIN LHSPLA-TA
A2: Semaine de référence : (se renseigne automatiquement à partir des onglets entité) | E2: Semaine du 25 au 29 mai 2026
A4: B. ACTIVITÉS RÉALISÉES — Semaine précédente (toutes entités)
A5: CAD – Chaîne d'Approvisionnement Décentralisée
A6: N° | B6: Titre de l'activité | C6: Objectifs | D6: Lieu | E6: Date(s) | F6: Principales recommandations / Résultats clés
A7: 1 | B7: 1.3-2.4 : Organiser des rencontres d'orientation logistique au niveau départemental | C7: · Présenter et analyser les résultats des activités logistiques au niveau des ESPC : rapportage et qualité des données rapportées ; disponibilités des stocks de produits traceurs et Système d’Alerte Précoce ; Gestion des stocks et utilisation de mSupply ; données de la File Active. · Identifier les problèmes à la mise en œuvre des activités au niveau des ESPC · Renforcer les capacités des gestionnaires de pharmacie des ESPC · Formuler des recommandations | D7: DS APA (26/05/2026) | E7: 46168 | F7: Nombre d'acteurs des ESPC présents : 14 acteurs; Les acteurs présents ont été sensibilités sur l'importance du respect du délai de dépôt des RM, coachés sur la qualité des données rapportées en passant en revue les erreurs courantes de rapportage (report mensuel des données; mauvaise unité de rapportage; items insuffisamment renseignés; erreurs de calculs; les incohérences régimes et indicateurs), au SAP et sa mise en oeuvre. Aussi, les acteurs ont été orientés sur la gestion des produits iCCM. Quelques recommandations : Organiser les services en responsabilisant les acteurs; Elaborer et transmettre dans les délais les RM; Valider en interne les données avant transmission des rapports au DS; Utiliser correctement toutes les fonctionnalités de mSupply; Estimer correctement les quantités à allouer en tenant compte des consommations réelles et des nombres de jours de rupture notifiés; Mettre en oeuvre le SAP pour anticiper tous risques de rupture et de péremptione
A8: 2 | B8: 1.3-2.2 : Organiser des visites d'assistance technique aux acteurs de la chaîne d'approvisionnement décentralisée | C8: Améliorer la qualité du rapportage, la qualité des prestations et de la gestion des produits et intrants des PNS | E8: Du 25 au 29/05/2026 | F8: Pas de visite réalisée cette semaine
